{"asctime": "2025-09-08 21:00:53,619", "name": "enterprise_rag", "levelname": "INFO", "message": "EnterpriseRAGService initialized"}
{"asctime": "2025-09-08 21:00:53,619", "name": "enterprise_rag", "levelname": "INFO", "message": "Starting RAG service initialization..."}
{"asctime": "2025-09-08 21:00:53,619", "name": "enterprise_rag", "levelname": "ERROR", "message": "error_occurred", "error_type": "ValueError", "error_message": "\"EnterpriseEmbedding\" object has no field \"use_cache\"", "context": {"stage": "initialization"}}
{"asctime": "2025-09-08 21:00:53,619", "name": "enterprise_rag", "levelname": "ERROR", "message": "error_occurred", "error_type": "ValueError", "error_message": "\"EnterpriseEmbedding\" object has no field \"use_cache\"", "context": {"stage": "main_initialization"}}
{"asctime": "2025-09-08 21:06:29,657", "name": "enterprise_rag", "levelname": "INFO", "message": "EnterpriseRAGService initialized"}
{"asctime": "2025-09-08 21:06:29,657", "name": "enterprise_rag", "levelname": "INFO", "message": "Starting RAG service initialization..."}
{"asctime": "2025-09-08 21:06:29,657", "name": "enterprise_rag", "levelname": "ERROR", "message": "error_occurred", "error_type": "ValueError", "error_message": "\"EnterpriseEmbedding\" object has no field \"use_cache\"", "context": {"stage": "initialization"}}
{"asctime": "2025-09-08 21:06:29,657", "name": "enterprise_rag", "levelname": "ERROR", "message": "error_occurred", "error_type": "ValueError", "error_message": "\"EnterpriseEmbedding\" object has no field \"use_cache\"", "context": {"stage": "main_initialization"}}
{"asctime": "2025-09-08 21:36:35,106", "name": "enterprise_rag", "levelname": "INFO", "message": "EnterpriseRAGService initialized"}
{"asctime": "2025-09-08 21:36:35,107", "name": "enterprise_rag", "levelname": "INFO", "message": "Starting RAG service initialization..."}
{"asctime": "2025-09-08 21:36:35,109", "name": "enterprise_rag", "levelname": "ERROR", "message": "Error occurred: ValueError - \"EnterpriseEmbedding\" object has no field \"use_cache\"\nTraceback (most recent call last):\n  File \"/home/ubuntu/PycharmProjects/pythonRAG/services/rag_service.py\", line 42, in initialize\n    self.embed_model = EnterpriseEmbedding(\n  File \"/home/ubuntu/PycharmProjects/pythonRAG/models/embeddings.py\", line 22, in __init__\n    self.use_cache = use_cache\n  File \"/home/ubuntu/miniconda3/envs/rag_agent/lib/python3.10/site-packages/pydantic/main.py\", line 997, in __setattr__\n    elif (setattr_handler := self._setattr_handler(name, value)) is not None:\n  File \"/home/ubuntu/miniconda3/envs/rag_agent/lib/python3.10/site-packages/pydantic/main.py\", line 1044, in _setattr_handler\n    raise ValueError(f'\"{cls.__name__}\" object has no field \"{name}\"')\nValueError: \"EnterpriseEmbedding\" object has no field \"use_cache\"\n", "error_type": "ValueError", "error_message": "\"EnterpriseEmbedding\" object has no field \"use_cache\"", "stack_trace": "Traceback (most recent call last):\n  File \"/home/ubuntu/PycharmProjects/pythonRAG/services/rag_service.py\", line 42, in initialize\n    self.embed_model = EnterpriseEmbedding(\n  File \"/home/ubuntu/PycharmProjects/pythonRAG/models/embeddings.py\", line 22, in __init__\n    self.use_cache = use_cache\n  File \"/home/ubuntu/miniconda3/envs/rag_agent/lib/python3.10/site-packages/pydantic/main.py\", line 997, in __setattr__\n    elif (setattr_handler := self._setattr_handler(name, value)) is not None:\n  File \"/home/ubuntu/miniconda3/envs/rag_agent/lib/python3.10/site-packages/pydantic/main.py\", line 1044, in _setattr_handler\n    raise ValueError(f'\"{cls.__name__}\" object has no field \"{name}\"')\nValueError: \"EnterpriseEmbedding\" object has no field \"use_cache\"\n", "context": {"stage": "initialization"}}
{"asctime": "2025-09-08 21:36:35,109", "name": "enterprise_rag", "levelname": "ERROR", "message": "Error occurred: ValueError - \"EnterpriseEmbedding\" object has no field \"use_cache\"\nTraceback (most recent call last):\n  File \"/home/ubuntu/PycharmProjects/pythonRAG/main.py\", line 27, in main\n    rag_service.initialize()\n  File \"/home/ubuntu/PycharmProjects/pythonRAG/services/rag_service.py\", line 42, in initialize\n    self.embed_model = EnterpriseEmbedding(\n  File \"/home/ubuntu/PycharmProjects/pythonRAG/models/embeddings.py\", line 22, in __init__\n    self.use_cache = use_cache\n  File \"/home/ubuntu/miniconda3/envs/rag_agent/lib/python3.10/site-packages/pydantic/main.py\", line 997, in __setattr__\n    elif (setattr_handler := self._setattr_handler(name, value)) is not None:\n  File \"/home/ubuntu/miniconda3/envs/rag_agent/lib/python3.10/site-packages/pydantic/main.py\", line 1044, in _setattr_handler\n    raise ValueError(f'\"{cls.__name__}\" object has no field \"{name}\"')\nValueError: \"EnterpriseEmbedding\" object has no field \"use_cache\"\n", "error_type": "ValueError", "error_message": "\"EnterpriseEmbedding\" object has no field \"use_cache\"", "stack_trace": "Traceback (most recent call last):\n  File \"/home/ubuntu/PycharmProjects/pythonRAG/main.py\", line 27, in main\n    rag_service.initialize()\n  File \"/home/ubuntu/PycharmProjects/pythonRAG/services/rag_service.py\", line 42, in initialize\n    self.embed_model = EnterpriseEmbedding(\n  File \"/home/ubuntu/PycharmProjects/pythonRAG/models/embeddings.py\", line 22, in __init__\n    self.use_cache = use_cache\n  File \"/home/ubuntu/miniconda3/envs/rag_agent/lib/python3.10/site-packages/pydantic/main.py\", line 997, in __setattr__\n    elif (setattr_handler := self._setattr_handler(name, value)) is not None:\n  File \"/home/ubuntu/miniconda3/envs/rag_agent/lib/python3.10/site-packages/pydantic/main.py\", line 1044, in _setattr_handler\n    raise ValueError(f'\"{cls.__name__}\" object has no field \"{name}\"')\nValueError: \"EnterpriseEmbedding\" object has no field \"use_cache\"\n", "context": {"stage": "main_initialization"}}
{"asctime": "2025-09-08 21:49:45,775", "name": "enterprise_rag", "levelname": "INFO", "message": "EnterpriseRAGService initialized"}
{"asctime": "2025-09-08 21:49:45,776", "name": "enterprise_rag", "levelname": "INFO", "message": "Starting RAG service initialization..."}
{"asctime": "2025-09-08 21:49:45,776", "name": "enterprise_rag", "levelname": "ERROR", "message": "Error occurred: AttributeError - 'EnterpriseEmbedding' object has no attribute '__pydantic_fields_set__'\nTraceback (most recent call last):\n  File \"/home/ubuntu/PycharmProjects/pythonRAG/services/rag_service.py\", line 42, in initialize\n    self.embed_model = EnterpriseEmbedding(\n  File \"/home/ubuntu/PycharmProjects/pythonRAG/models/embeddings.py\", line 31, in __init__\n    self.use_cache = use_cache\n  File \"/home/ubuntu/miniconda3/envs/rag_agent/lib/python3.10/site-packages/pydantic/main.py\", line 998, in __setattr__\n    setattr_handler(self, name, value)  # call here to not memo on possibly unknown fields\n  File \"/home/ubuntu/miniconda3/envs/rag_agent/lib/python3.10/site-packages/pydantic/main.py\", line 99, in _model_field_setattr_handler\n    model.__pydantic_fields_set__.add(name)\n  File \"/home/ubuntu/miniconda3/envs/rag_agent/lib/python3.10/site-packages/pydantic/main.py\", line 988, in __getattr__\n    return super().__getattribute__(item)  # Raises AttributeError if appropriate\nAttributeError: 'EnterpriseEmbedding' object has no attribute '__pydantic_fields_set__'\n", "error_type": "AttributeError", "error_message": "'EnterpriseEmbedding' object has no attribute '__pydantic_fields_set__'", "stack_trace": "Traceback (most recent call last):\n  File \"/home/ubuntu/PycharmProjects/pythonRAG/services/rag_service.py\", line 42, in initialize\n    self.embed_model = EnterpriseEmbedding(\n  File \"/home/ubuntu/PycharmProjects/pythonRAG/models/embeddings.py\", line 31, in __init__\n    self.use_cache = use_cache\n  File \"/home/ubuntu/miniconda3/envs/rag_agent/lib/python3.10/site-packages/pydantic/main.py\", line 998, in __setattr__\n    setattr_handler(self, name, value)  # call here to not memo on possibly unknown fields\n  File \"/home/ubuntu/miniconda3/envs/rag_agent/lib/python3.10/site-packages/pydantic/main.py\", line 99, in _model_field_setattr_handler\n    model.__pydantic_fields_set__.add(name)\n  File \"/home/ubuntu/miniconda3/envs/rag_agent/lib/python3.10/site-packages/pydantic/main.py\", line 988, in __getattr__\n    return super().__getattribute__(item)  # Raises AttributeError if appropriate\nAttributeError: 'EnterpriseEmbedding' object has no attribute '__pydantic_fields_set__'\n", "context": {"stage": "initialization"}}
{"asctime": "2025-09-08 21:49:45,777", "name": "enterprise_rag", "levelname": "ERROR", "message": "Error occurred: AttributeError - 'EnterpriseEmbedding' object has no attribute '__pydantic_fields_set__'\nTraceback (most recent call last):\n  File \"/home/ubuntu/PycharmProjects/pythonRAG/main.py\", line 27, in main\n    rag_service.initialize()\n  File \"/home/ubuntu/PycharmProjects/pythonRAG/services/rag_service.py\", line 42, in initialize\n    self.embed_model = EnterpriseEmbedding(\n  File \"/home/ubuntu/PycharmProjects/pythonRAG/models/embeddings.py\", line 31, in __init__\n    self.use_cache = use_cache\n  File \"/home/ubuntu/miniconda3/envs/rag_agent/lib/python3.10/site-packages/pydantic/main.py\", line 998, in __setattr__\n    setattr_handler(self, name, value)  # call here to not memo on possibly unknown fields\n  File \"/home/ubuntu/miniconda3/envs/rag_agent/lib/python3.10/site-packages/pydantic/main.py\", line 99, in _model_field_setattr_handler\n    model.__pydantic_fields_set__.add(name)\n  File \"/home/ubuntu/miniconda3/envs/rag_agent/lib/python3.10/site-packages/pydantic/main.py\", line 988, in __getattr__\n    return super().__getattribute__(item)  # Raises AttributeError if appropriate\nAttributeError: 'EnterpriseEmbedding' object has no attribute '__pydantic_fields_set__'\n", "error_type": "AttributeError", "error_message": "'EnterpriseEmbedding' object has no attribute '__pydantic_fields_set__'", "stack_trace": "Traceback (most recent call last):\n  File \"/home/ubuntu/PycharmProjects/pythonRAG/main.py\", line 27, in main\n    rag_service.initialize()\n  File \"/home/ubuntu/PycharmProjects/pythonRAG/services/rag_service.py\", line 42, in initialize\n    self.embed_model = EnterpriseEmbedding(\n  File \"/home/ubuntu/PycharmProjects/pythonRAG/models/embeddings.py\", line 31, in __init__\n    self.use_cache = use_cache\n  File \"/home/ubuntu/miniconda3/envs/rag_agent/lib/python3.10/site-packages/pydantic/main.py\", line 998, in __setattr__\n    setattr_handler(self, name, value)  # call here to not memo on possibly unknown fields\n  File \"/home/ubuntu/miniconda3/envs/rag_agent/lib/python3.10/site-packages/pydantic/main.py\", line 99, in _model_field_setattr_handler\n    model.__pydantic_fields_set__.add(name)\n  File \"/home/ubuntu/miniconda3/envs/rag_agent/lib/python3.10/site-packages/pydantic/main.py\", line 988, in __getattr__\n    return super().__getattribute__(item)  # Raises AttributeError if appropriate\nAttributeError: 'EnterpriseEmbedding' object has no attribute '__pydantic_fields_set__'\n", "context": {"stage": "main_initialization"}}
{"asctime": "2025-09-08 21:50:14,138", "name": "enterprise_rag", "levelname": "INFO", "message": "EnterpriseRAGService initialized"}
{"asctime": "2025-09-08 21:50:14,138", "name": "enterprise_rag", "levelname": "INFO", "message": "Starting RAG service initialization..."}
{"asctime": "2025-09-08 21:50:14,138", "name": "enterprise_rag", "levelname": "ERROR", "message": "Error occurred: AttributeError - 'EnterpriseEmbedding' object has no attribute '__pydantic_fields_set__'\nTraceback (most recent call last):\n  File \"/home/ubuntu/PycharmProjects/pythonRAG/services/rag_service.py\", line 42, in initialize\n    self.embed_model = EnterpriseEmbedding(\n  File \"/home/ubuntu/PycharmProjects/pythonRAG/models/embeddings.py\", line 32, in __init__\n    super().__setattr__('max_length', max_length)\n  File \"/home/ubuntu/miniconda3/envs/rag_agent/lib/python3.10/site-packages/pydantic/main.py\", line 998, in __setattr__\n    setattr_handler(self, name, value)  # call here to not memo on possibly unknown fields\n  File \"/home/ubuntu/miniconda3/envs/rag_agent/lib/python3.10/site-packages/pydantic/main.py\", line 99, in _model_field_setattr_handler\n    model.__pydantic_fields_set__.add(name)\n  File \"/home/ubuntu/miniconda3/envs/rag_agent/lib/python3.10/site-packages/pydantic/main.py\", line 988, in __getattr__\n    return super().__getattribute__(item)  # Raises AttributeError if appropriate\nAttributeError: 'EnterpriseEmbedding' object has no attribute '__pydantic_fields_set__'\n", "error_type": "AttributeError", "error_message": "'EnterpriseEmbedding' object has no attribute '__pydantic_fields_set__'", "stack_trace": "Traceback (most recent call last):\n  File \"/home/ubuntu/PycharmProjects/pythonRAG/services/rag_service.py\", line 42, in initialize\n    self.embed_model = EnterpriseEmbedding(\n  File \"/home/ubuntu/PycharmProjects/pythonRAG/models/embeddings.py\", line 32, in __init__\n    super().__setattr__('max_length', max_length)\n  File \"/home/ubuntu/miniconda3/envs/rag_agent/lib/python3.10/site-packages/pydantic/main.py\", line 998, in __setattr__\n    setattr_handler(self, name, value)  # call here to not memo on possibly unknown fields\n  File \"/home/ubuntu/miniconda3/envs/rag_agent/lib/python3.10/site-packages/pydantic/main.py\", line 99, in _model_field_setattr_handler\n    model.__pydantic_fields_set__.add(name)\n  File \"/home/ubuntu/miniconda3/envs/rag_agent/lib/python3.10/site-packages/pydantic/main.py\", line 988, in __getattr__\n    return super().__getattribute__(item)  # Raises AttributeError if appropriate\nAttributeError: 'EnterpriseEmbedding' object has no attribute '__pydantic_fields_set__'\n", "context": {"stage": "initialization"}}
{"asctime": "2025-09-08 21:50:14,139", "name": "enterprise_rag", "levelname": "ERROR", "message": "Error occurred: AttributeError - 'EnterpriseEmbedding' object has no attribute '__pydantic_fields_set__'\nTraceback (most recent call last):\n  File \"/home/ubuntu/PycharmProjects/pythonRAG/main.py\", line 27, in main\n    rag_service.initialize()\n  File \"/home/ubuntu/PycharmProjects/pythonRAG/services/rag_service.py\", line 42, in initialize\n    self.embed_model = EnterpriseEmbedding(\n  File \"/home/ubuntu/PycharmProjects/pythonRAG/models/embeddings.py\", line 32, in __init__\n    super().__setattr__('max_length', max_length)\n  File \"/home/ubuntu/miniconda3/envs/rag_agent/lib/python3.10/site-packages/pydantic/main.py\", line 998, in __setattr__\n    setattr_handler(self, name, value)  # call here to not memo on possibly unknown fields\n  File \"/home/ubuntu/miniconda3/envs/rag_agent/lib/python3.10/site-packages/pydantic/main.py\", line 99, in _model_field_setattr_handler\n    model.__pydantic_fields_set__.add(name)\n  File \"/home/ubuntu/miniconda3/envs/rag_agent/lib/python3.10/site-packages/pydantic/main.py\", line 988, in __getattr__\n    return super().__getattribute__(item)  # Raises AttributeError if appropriate\nAttributeError: 'EnterpriseEmbedding' object has no attribute '__pydantic_fields_set__'\n", "error_type": "AttributeError", "error_message": "'EnterpriseEmbedding' object has no attribute '__pydantic_fields_set__'", "stack_trace": "Traceback (most recent call last):\n  File \"/home/ubuntu/PycharmProjects/pythonRAG/main.py\", line 27, in main\n    rag_service.initialize()\n  File \"/home/ubuntu/PycharmProjects/pythonRAG/services/rag_service.py\", line 42, in initialize\n    self.embed_model = EnterpriseEmbedding(\n  File \"/home/ubuntu/PycharmProjects/pythonRAG/models/embeddings.py\", line 32, in __init__\n    super().__setattr__('max_length', max_length)\n  File \"/home/ubuntu/miniconda3/envs/rag_agent/lib/python3.10/site-packages/pydantic/main.py\", line 998, in __setattr__\n    setattr_handler(self, name, value)  # call here to not memo on possibly unknown fields\n  File \"/home/ubuntu/miniconda3/envs/rag_agent/lib/python3.10/site-packages/pydantic/main.py\", line 99, in _model_field_setattr_handler\n    model.__pydantic_fields_set__.add(name)\n  File \"/home/ubuntu/miniconda3/envs/rag_agent/lib/python3.10/site-packages/pydantic/main.py\", line 988, in __getattr__\n    return super().__getattribute__(item)  # Raises AttributeError if appropriate\nAttributeError: 'EnterpriseEmbedding' object has no attribute '__pydantic_fields_set__'\n", "context": {"stage": "main_initialization"}}
{"asctime": "2025-09-08 21:51:09,068", "name": "enterprise_rag", "levelname": "INFO", "message": "EnterpriseRAGService initialized"}
{"asctime": "2025-09-08 21:51:09,068", "name": "enterprise_rag", "levelname": "INFO", "message": "Starting RAG service initialization..."}
{"asctime": "2025-09-08 21:51:09,069", "name": "enterprise_rag", "levelname": "ERROR", "message": "Error occurred: AttributeError - 'EnterpriseEmbedding' object has no attribute '__pydantic_fields_set__'\nTraceback (most recent call last):\n  File \"/home/ubuntu/PycharmProjects/pythonRAG/services/rag_service.py\", line 42, in initialize\n    self.embed_model = EnterpriseEmbedding(\n  File \"/home/ubuntu/PycharmProjects/pythonRAG/models/embeddings.py\", line 31, in __init__\n    self.use_cache = use_cache\n  File \"/home/ubuntu/miniconda3/envs/rag_agent/lib/python3.10/site-packages/pydantic/main.py\", line 998, in __setattr__\n    setattr_handler(self, name, value)  # call here to not memo on possibly unknown fields\n  File \"/home/ubuntu/miniconda3/envs/rag_agent/lib/python3.10/site-packages/pydantic/main.py\", line 99, in _model_field_setattr_handler\n    model.__pydantic_fields_set__.add(name)\n  File \"/home/ubuntu/miniconda3/envs/rag_agent/lib/python3.10/site-packages/pydantic/main.py\", line 988, in __getattr__\n    return super().__getattribute__(item)  # Raises AttributeError if appropriate\nAttributeError: 'EnterpriseEmbedding' object has no attribute '__pydantic_fields_set__'\n", "error_type": "AttributeError", "error_message": "'EnterpriseEmbedding' object has no attribute '__pydantic_fields_set__'", "stack_trace": "Traceback (most recent call last):\n  File \"/home/ubuntu/PycharmProjects/pythonRAG/services/rag_service.py\", line 42, in initialize\n    self.embed_model = EnterpriseEmbedding(\n  File \"/home/ubuntu/PycharmProjects/pythonRAG/models/embeddings.py\", line 31, in __init__\n    self.use_cache = use_cache\n  File \"/home/ubuntu/miniconda3/envs/rag_agent/lib/python3.10/site-packages/pydantic/main.py\", line 998, in __setattr__\n    setattr_handler(self, name, value)  # call here to not memo on possibly unknown fields\n  File \"/home/ubuntu/miniconda3/envs/rag_agent/lib/python3.10/site-packages/pydantic/main.py\", line 99, in _model_field_setattr_handler\n    model.__pydantic_fields_set__.add(name)\n  File \"/home/ubuntu/miniconda3/envs/rag_agent/lib/python3.10/site-packages/pydantic/main.py\", line 988, in __getattr__\n    return super().__getattribute__(item)  # Raises AttributeError if appropriate\nAttributeError: 'EnterpriseEmbedding' object has no attribute '__pydantic_fields_set__'\n", "context": {"stage": "initialization"}}
{"asctime": "2025-09-08 21:51:09,069", "name": "enterprise_rag", "levelname": "ERROR", "message": "Error occurred: AttributeError - 'EnterpriseEmbedding' object has no attribute '__pydantic_fields_set__'\nTraceback (most recent call last):\n  File \"/home/ubuntu/PycharmProjects/pythonRAG/main.py\", line 27, in main\n    rag_service.initialize()\n  File \"/home/ubuntu/PycharmProjects/pythonRAG/services/rag_service.py\", line 42, in initialize\n    self.embed_model = EnterpriseEmbedding(\n  File \"/home/ubuntu/PycharmProjects/pythonRAG/models/embeddings.py\", line 31, in __init__\n    self.use_cache = use_cache\n  File \"/home/ubuntu/miniconda3/envs/rag_agent/lib/python3.10/site-packages/pydantic/main.py\", line 998, in __setattr__\n    setattr_handler(self, name, value)  # call here to not memo on possibly unknown fields\n  File \"/home/ubuntu/miniconda3/envs/rag_agent/lib/python3.10/site-packages/pydantic/main.py\", line 99, in _model_field_setattr_handler\n    model.__pydantic_fields_set__.add(name)\n  File \"/home/ubuntu/miniconda3/envs/rag_agent/lib/python3.10/site-packages/pydantic/main.py\", line 988, in __getattr__\n    return super().__getattribute__(item)  # Raises AttributeError if appropriate\nAttributeError: 'EnterpriseEmbedding' object has no attribute '__pydantic_fields_set__'\n", "error_type": "AttributeError", "error_message": "'EnterpriseEmbedding' object has no attribute '__pydantic_fields_set__'", "stack_trace": "Traceback (most recent call last):\n  File \"/home/ubuntu/PycharmProjects/pythonRAG/main.py\", line 27, in main\n    rag_service.initialize()\n  File \"/home/ubuntu/PycharmProjects/pythonRAG/services/rag_service.py\", line 42, in initialize\n    self.embed_model = EnterpriseEmbedding(\n  File \"/home/ubuntu/PycharmProjects/pythonRAG/models/embeddings.py\", line 31, in __init__\n    self.use_cache = use_cache\n  File \"/home/ubuntu/miniconda3/envs/rag_agent/lib/python3.10/site-packages/pydantic/main.py\", line 998, in __setattr__\n    setattr_handler(self, name, value)  # call here to not memo on possibly unknown fields\n  File \"/home/ubuntu/miniconda3/envs/rag_agent/lib/python3.10/site-packages/pydantic/main.py\", line 99, in _model_field_setattr_handler\n    model.__pydantic_fields_set__.add(name)\n  File \"/home/ubuntu/miniconda3/envs/rag_agent/lib/python3.10/site-packages/pydantic/main.py\", line 988, in __getattr__\n    return super().__getattribute__(item)  # Raises AttributeError if appropriate\nAttributeError: 'EnterpriseEmbedding' object has no attribute '__pydantic_fields_set__'\n", "context": {"stage": "main_initialization"}}
{"asctime": "2025-09-08 21:57:12,255", "name": "enterprise_rag", "levelname": "INFO", "message": "EnterpriseRAGService initialized"}
{"asctime": "2025-09-08 21:57:12,256", "name": "enterprise_rag", "levelname": "INFO", "message": "Starting RAG service initialization..."}
{"asctime": "2025-09-08 21:57:13,487", "name": "enterprise_rag", "levelname": "INFO", "message": "Embedding model loaded on cuda"}
{"asctime": "2025-09-08 21:57:23,064", "name": "enterprise_rag", "levelname": "INFO", "message": "Processing file: data/TCM.json"}
{"asctime": "2025-09-08 21:57:23,066", "name": "enterprise_rag", "levelname": "INFO", "message": "Processed 100 documents from data"}
{"asctime": "2025-09-08 21:57:23,082", "name": "enterprise_rag", "levelname": "INFO", "message": "Created 100 nodes from 100 documents"}
{"asctime": "2025-09-08 21:57:33,219", "name": "enterprise_rag", "levelname": "ERROR", "message": "Error occurred: MilvusException - <MilvusException: (code=2, message=Fail connecting to server on localhost:19530, illegal connection params or server unavailable)>\nTraceback (most recent call last):\n  File \"/home/ubuntu/PycharmProjects/pythonRAG/services/rag_service.py\", line 69, in initialize\n    self.vector_store = MilvusVectorStore(\n  File \"/home/ubuntu/miniconda3/envs/rag_agent/lib/python3.10/site-packages/llama_index/vector_stores/milvus/base.py\", line 315, in __init__\n    self._milvusclient = MilvusClient(\n  File \"/home/ubuntu/miniconda3/envs/rag_agent/lib/python3.10/site-packages/pymilvus/milvus_client/milvus_client.py\", line 65, in __init__\n    self._using = create_connection(\n  File \"/home/ubuntu/miniconda3/envs/rag_agent/lib/python3.10/site-packages/pymilvus/milvus_client/_utils.py\", line 49, in create_connection\n    raise ex from ex\n  File \"/home/ubuntu/miniconda3/envs/rag_agent/lib/python3.10/site-packages/pymilvus/milvus_client/_utils.py\", line 44, in create_connection\n    connections.connect(\n  File \"/home/ubuntu/miniconda3/envs/rag_agent/lib/python3.10/site-packages/pymilvus/orm/connections.py\", line 466, in connect\n    connect_milvus(**kwargs, user=user, password=password, token=token, db_name=db_name)\n  File \"/home/ubuntu/miniconda3/envs/rag_agent/lib/python3.10/site-packages/pymilvus/orm/connections.py\", line 420, in connect_milvus\n    raise e from e\n  File \"/home/ubuntu/miniconda3/envs/rag_agent/lib/python3.10/site-packages/pymilvus/orm/connections.py\", line 412, in connect_milvus\n    gh._wait_for_channel_ready(timeout=timeout)\n  File \"/home/ubuntu/miniconda3/envs/rag_agent/lib/python3.10/site-packages/pymilvus/client/grpc_handler.py\", line 162, in _wait_for_channel_ready\n    raise MilvusException(\npymilvus.exceptions.MilvusException: <MilvusException: (code=2, message=Fail connecting to server on localhost:19530, illegal connection params or server unavailable)>\n", "error_type": "MilvusException", "error_message": "<MilvusException: (code=2, message=Fail connecting to server on localhost:19530, illegal connection params or server unavailable)>", "stack_trace": "Traceback (most recent call last):\n  File \"/home/ubuntu/PycharmProjects/pythonRAG/services/rag_service.py\", line 69, in initialize\n    self.vector_store = MilvusVectorStore(\n  File \"/home/ubuntu/miniconda3/envs/rag_agent/lib/python3.10/site-packages/llama_index/vector_stores/milvus/base.py\", line 315, in __init__\n    self._milvusclient = MilvusClient(\n  File \"/home/ubuntu/miniconda3/envs/rag_agent/lib/python3.10/site-packages/pymilvus/milvus_client/milvus_client.py\", line 65, in __init__\n    self._using = create_connection(\n  File \"/home/ubuntu/miniconda3/envs/rag_agent/lib/python3.10/site-packages/pymilvus/milvus_client/_utils.py\", line 49, in create_connection\n    raise ex from ex\n  File \"/home/ubuntu/miniconda3/envs/rag_agent/lib/python3.10/site-packages/pymilvus/milvus_client/_utils.py\", line 44, in create_connection\n    connections.connect(\n  File \"/home/ubuntu/miniconda3/envs/rag_agent/lib/python3.10/site-packages/pymilvus/orm/connections.py\", line 466, in connect\n    connect_milvus(**kwargs, user=user, password=password, token=token, db_name=db_name)\n  File \"/home/ubuntu/miniconda3/envs/rag_agent/lib/python3.10/site-packages/pymilvus/orm/connections.py\", line 420, in connect_milvus\n    raise e from e\n  File \"/home/ubuntu/miniconda3/envs/rag_agent/lib/python3.10/site-packages/pymilvus/orm/connections.py\", line 412, in connect_milvus\n    gh._wait_for_channel_ready(timeout=timeout)\n  File \"/home/ubuntu/miniconda3/envs/rag_agent/lib/python3.10/site-packages/pymilvus/client/grpc_handler.py\", line 162, in _wait_for_channel_ready\n    raise MilvusException(\npymilvus.exceptions.MilvusException: <MilvusException: (code=2, message=Fail connecting to server on localhost:19530, illegal connection params or server unavailable)>\n", "context": {"stage": "initialization"}}
{"asctime": "2025-09-08 21:57:33,220", "name": "enterprise_rag", "levelname": "ERROR", "message": "Error occurred: MilvusException - <MilvusException: (code=2, message=Fail connecting to server on localhost:19530, illegal connection params or server unavailable)>\nTraceback (most recent call last):\n  File \"/home/ubuntu/PycharmProjects/pythonRAG/main.py\", line 27, in main\n    rag_service.initialize()\n  File \"/home/ubuntu/PycharmProjects/pythonRAG/services/rag_service.py\", line 69, in initialize\n    self.vector_store = MilvusVectorStore(\n  File \"/home/ubuntu/miniconda3/envs/rag_agent/lib/python3.10/site-packages/llama_index/vector_stores/milvus/base.py\", line 315, in __init__\n    self._milvusclient = MilvusClient(\n  File \"/home/ubuntu/miniconda3/envs/rag_agent/lib/python3.10/site-packages/pymilvus/milvus_client/milvus_client.py\", line 65, in __init__\n    self._using = create_connection(\n  File \"/home/ubuntu/miniconda3/envs/rag_agent/lib/python3.10/site-packages/pymilvus/milvus_client/_utils.py\", line 49, in create_connection\n    raise ex from ex\n  File \"/home/ubuntu/miniconda3/envs/rag_agent/lib/python3.10/site-packages/pymilvus/milvus_client/_utils.py\", line 44, in create_connection\n    connections.connect(\n  File \"/home/ubuntu/miniconda3/envs/rag_agent/lib/python3.10/site-packages/pymilvus/orm/connections.py\", line 466, in connect\n    connect_milvus(**kwargs, user=user, password=password, token=token, db_name=db_name)\n  File \"/home/ubuntu/miniconda3/envs/rag_agent/lib/python3.10/site-packages/pymilvus/orm/connections.py\", line 420, in connect_milvus\n    raise e from e\n  File \"/home/ubuntu/miniconda3/envs/rag_agent/lib/python3.10/site-packages/pymilvus/orm/connections.py\", line 412, in connect_milvus\n    gh._wait_for_channel_ready(timeout=timeout)\n  File \"/home/ubuntu/miniconda3/envs/rag_agent/lib/python3.10/site-packages/pymilvus/client/grpc_handler.py\", line 162, in _wait_for_channel_ready\n    raise MilvusException(\npymilvus.exceptions.MilvusException: <MilvusException: (code=2, message=Fail connecting to server on localhost:19530, illegal connection params or server unavailable)>\n", "error_type": "MilvusException", "error_message": "<MilvusException: (code=2, message=Fail connecting to server on localhost:19530, illegal connection params or server unavailable)>", "stack_trace": "Traceback (most recent call last):\n  File \"/home/ubuntu/PycharmProjects/pythonRAG/main.py\", line 27, in main\n    rag_service.initialize()\n  File \"/home/ubuntu/PycharmProjects/pythonRAG/services/rag_service.py\", line 69, in initialize\n    self.vector_store = MilvusVectorStore(\n  File \"/home/ubuntu/miniconda3/envs/rag_agent/lib/python3.10/site-packages/llama_index/vector_stores/milvus/base.py\", line 315, in __init__\n    self._milvusclient = MilvusClient(\n  File \"/home/ubuntu/miniconda3/envs/rag_agent/lib/python3.10/site-packages/pymilvus/milvus_client/milvus_client.py\", line 65, in __init__\n    self._using = create_connection(\n  File \"/home/ubuntu/miniconda3/envs/rag_agent/lib/python3.10/site-packages/pymilvus/milvus_client/_utils.py\", line 49, in create_connection\n    raise ex from ex\n  File \"/home/ubuntu/miniconda3/envs/rag_agent/lib/python3.10/site-packages/pymilvus/milvus_client/_utils.py\", line 44, in create_connection\n    connections.connect(\n  File \"/home/ubuntu/miniconda3/envs/rag_agent/lib/python3.10/site-packages/pymilvus/orm/connections.py\", line 466, in connect\n    connect_milvus(**kwargs, user=user, password=password, token=token, db_name=db_name)\n  File \"/home/ubuntu/miniconda3/envs/rag_agent/lib/python3.10/site-packages/pymilvus/orm/connections.py\", line 420, in connect_milvus\n    raise e from e\n  File \"/home/ubuntu/miniconda3/envs/rag_agent/lib/python3.10/site-packages/pymilvus/orm/connections.py\", line 412, in connect_milvus\n    gh._wait_for_channel_ready(timeout=timeout)\n  File \"/home/ubuntu/miniconda3/envs/rag_agent/lib/python3.10/site-packages/pymilvus/client/grpc_handler.py\", line 162, in _wait_for_channel_ready\n    raise MilvusException(\npymilvus.exceptions.MilvusException: <MilvusException: (code=2, message=Fail connecting to server on localhost:19530, illegal connection params or server unavailable)>\n", "context": {"stage": "main_initialization"}}
{"asctime": "2025-09-08 21:58:23,664", "name": "enterprise_rag", "levelname": "INFO", "message": "EnterpriseRAGService initialized"}
{"asctime": "2025-09-08 21:58:23,664", "name": "enterprise_rag", "levelname": "INFO", "message": "Starting RAG service initialization..."}
{"asctime": "2025-09-08 21:58:24,840", "name": "enterprise_rag", "levelname": "INFO", "message": "Embedding model loaded on cuda"}
{"asctime": "2025-09-08 21:58:32,730", "name": "enterprise_rag", "levelname": "INFO", "message": "Processing file: data/TCM.json"}
{"asctime": "2025-09-08 21:58:32,732", "name": "enterprise_rag", "levelname": "INFO", "message": "Processed 100 documents from data"}
{"asctime": "2025-09-08 21:58:32,746", "name": "enterprise_rag", "levelname": "INFO", "message": "Created 100 nodes from 100 documents"}
{"asctime": "2025-09-08 21:58:34,590", "name": "enterprise_rag", "levelname": "INFO", "message": "Embedded 10 sentences in 0.45s"}
{"asctime": "2025-09-08 21:58:34,720", "name": "enterprise_rag", "levelname": "INFO", "message": "Embedded 10 sentences in 0.13s"}
{"asctime": "2025-09-08 21:58:34,846", "name": "enterprise_rag", "levelname": "INFO", "message": "Embedded 10 sentences in 0.12s"}
{"asctime": "2025-09-08 21:58:34,959", "name": "enterprise_rag", "levelname": "INFO", "message": "Embedded 10 sentences in 0.11s"}
{"asctime": "2025-09-08 21:58:35,070", "name": "enterprise_rag", "levelname": "INFO", "message": "Embedded 10 sentences in 0.11s"}
{"asctime": "2025-09-08 21:58:35,190", "name": "enterprise_rag", "levelname": "INFO", "message": "Embedded 10 sentences in 0.12s"}
{"asctime": "2025-09-08 21:58:35,302", "name": "enterprise_rag", "levelname": "INFO", "message": "Embedded 10 sentences in 0.11s"}
{"asctime": "2025-09-08 21:58:35,413", "name": "enterprise_rag", "levelname": "INFO", "message": "Embedded 10 sentences in 0.11s"}
{"asctime": "2025-09-08 21:58:35,520", "name": "enterprise_rag", "levelname": "INFO", "message": "Embedded 10 sentences in 0.11s"}
{"asctime": "2025-09-08 21:58:35,627", "name": "enterprise_rag", "levelname": "INFO", "message": "Embedded 10 sentences in 0.11s"}
{"asctime": "2025-09-08 21:58:35,668", "name": "enterprise_rag", "levelname": "ERROR", "message": "Error occurred: NameError - name 'torch' is not defined\nTraceback (most recent call last):\n  File \"/home/ubuntu/PycharmProjects/pythonRAG/services/retriever.py\", line 41, in __init__\n    device=\"cuda\" if torch.cuda.is_available() else \"cpu\"\nNameError: name 'torch' is not defined\n", "error_type": "NameError", "error_message": "name 'torch' is not defined", "stack_trace": "Traceback (most recent call last):\n  File \"/home/ubuntu/PycharmProjects/pythonRAG/services/retriever.py\", line 41, in __init__\n    device=\"cuda\" if torch.cuda.is_available() else \"cpu\"\nNameError: name 'torch' is not defined\n", "context": {"model_path": "/home/ubuntu/PycharmProjects/pythonRAG/models/BAAI/bge-reranker-base"}}
{"asctime": "2025-09-08 21:58:35,669", "name": "enterprise_rag", "levelname": "ERROR", "message": "Error occurred: NameError - name 'torch' is not defined\nTraceback (most recent call last):\n  File \"/home/ubuntu/PycharmProjects/pythonRAG/services/rag_service.py\", line 83, in initialize\n    self.retriever = EnterpriseRetriever(\n  File \"/home/ubuntu/PycharmProjects/pythonRAG/services/retriever.py\", line 41, in __init__\n    device=\"cuda\" if torch.cuda.is_available() else \"cpu\"\nNameError: name 'torch' is not defined\n", "error_type": "NameError", "error_message": "name 'torch' is not defined", "stack_trace": "Traceback (most recent call last):\n  File \"/home/ubuntu/PycharmProjects/pythonRAG/services/rag_service.py\", line 83, in initialize\n    self.retriever = EnterpriseRetriever(\n  File \"/home/ubuntu/PycharmProjects/pythonRAG/services/retriever.py\", line 41, in __init__\n    device=\"cuda\" if torch.cuda.is_available() else \"cpu\"\nNameError: name 'torch' is not defined\n", "context": {"stage": "initialization"}}
{"asctime": "2025-09-08 21:58:35,669", "name": "enterprise_rag", "levelname": "ERROR", "message": "Error occurred: NameError - name 'torch' is not defined\nTraceback (most recent call last):\n  File \"/home/ubuntu/PycharmProjects/pythonRAG/main.py\", line 27, in main\n    rag_service.initialize()\n  File \"/home/ubuntu/PycharmProjects/pythonRAG/services/rag_service.py\", line 83, in initialize\n    self.retriever = EnterpriseRetriever(\n  File \"/home/ubuntu/PycharmProjects/pythonRAG/services/retriever.py\", line 41, in __init__\n    device=\"cuda\" if torch.cuda.is_available() else \"cpu\"\nNameError: name 'torch' is not defined\n", "error_type": "NameError", "error_message": "name 'torch' is not defined", "stack_trace": "Traceback (most recent call last):\n  File \"/home/ubuntu/PycharmProjects/pythonRAG/main.py\", line 27, in main\n    rag_service.initialize()\n  File \"/home/ubuntu/PycharmProjects/pythonRAG/services/rag_service.py\", line 83, in initialize\n    self.retriever = EnterpriseRetriever(\n  File \"/home/ubuntu/PycharmProjects/pythonRAG/services/retriever.py\", line 41, in __init__\n    device=\"cuda\" if torch.cuda.is_available() else \"cpu\"\nNameError: name 'torch' is not defined\n", "context": {"stage": "main_initialization"}}
{"asctime": "2025-09-08 22:01:46,927", "name": "enterprise_rag", "levelname": "INFO", "message": "EnterpriseRAGService initialized"}
{"asctime": "2025-09-08 22:01:46,927", "name": "enterprise_rag", "levelname": "INFO", "message": "Starting RAG service initialization..."}
{"asctime": "2025-09-08 22:01:47,937", "name": "enterprise_rag", "levelname": "INFO", "message": "Embedding model loaded on cuda"}
{"asctime": "2025-09-08 22:01:54,352", "name": "enterprise_rag", "levelname": "INFO", "message": "Processing file: data/TCM.json"}
{"asctime": "2025-09-08 22:01:54,354", "name": "enterprise_rag", "levelname": "INFO", "message": "Processed 100 documents from data"}
{"asctime": "2025-09-08 22:01:54,367", "name": "enterprise_rag", "levelname": "INFO", "message": "Created 100 nodes from 100 documents"}
{"asctime": "2025-09-08 22:01:57,795", "name": "enterprise_rag", "levelname": "INFO", "message": "Reranker model loaded successfully"}
{"asctime": "2025-09-08 22:01:57,795", "name": "enterprise_rag", "levelname": "INFO", "message": "RAG service initialization completed successfully"}
{"asctime": "2025-09-08 22:03:17,127", "name": "enterprise_rag", "levelname": "INFO", "message": "query_received", "query": "\u5934\u90e8\u6c89\u91cd\u75db\u80c0\uff0c\u75db\u52bf\u7f13\u6162\uff0c\u9047\u9634\u96e8\u5929\u52a0\u91cd", "user_id": "user_console_001", "metadata": {}}
{"asctime": "2025-09-08 22:03:17,486", "name": "enterprise_rag", "levelname": "INFO", "message": "Embedded 1 sentences in 0.36s"}
{"asctime": "2025-09-08 22:03:17,514", "name": "enterprise_rag", "levelname": "INFO", "message": "Dense retrieval: 20 results"}
{"asctime": "2025-09-08 22:03:17,514", "name": "enterprise_rag", "levelname": "INFO", "message": "Sparse retrieval: 40 results"}
{"asctime": "2025-09-08 22:03:17,515", "name": "enterprise_rag", "levelname": "ERROR", "message": "Error occurred: AttributeError - 'RetrievalConfig' object has no attribute 'batch_size'\nTraceback (most recent call last):\n  File \"/home/ubuntu/PycharmProjects/pythonRAG/services/retriever.py\", line 125, in _rerank_results\n    scores = self.reranker.predict(pairs, batch_size=self.config.batch_size)\nAttributeError: 'RetrievalConfig' object has no attribute 'batch_size'\n", "error_type": "AttributeError", "error_message": "'RetrievalConfig' object has no attribute 'batch_size'", "stack_trace": "Traceback (most recent call last):\n  File \"/home/ubuntu/PycharmProjects/pythonRAG/services/retriever.py\", line 125, in _rerank_results\n    scores = self.reranker.predict(pairs, batch_size=self.config.batch_size)\nAttributeError: 'RetrievalConfig' object has no attribute 'batch_size'\n", "context": {"query": "\u5934\u90e8\u6c89\u91cd\u75db\u80c0\uff0c\u75db\u52bf\u7f13\u6162\uff0c\u9047\u9634\u96e8\u5929\u52a0\u91cd", "num_results": 60}}
{"asctime": "2025-09-08 22:03:17,515", "name": "enterprise_rag", "levelname": "INFO", "message": "Initial rerank: top score = 0.8132, good results = 8"}
{"asctime": "2025-09-08 22:03:17,515", "name": "enterprise_rag", "levelname": "ERROR", "message": "Error occurred: AttributeError - 'RetrievalConfig' object has no attribute 'batch_size'\nTraceback (most recent call last):\n  File \"/home/ubuntu/PycharmProjects/pythonRAG/services/retriever.py\", line 125, in _rerank_results\n    scores = self.reranker.predict(pairs, batch_size=self.config.batch_size)\nAttributeError: 'RetrievalConfig' object has no attribute 'batch_size'\n", "error_type": "AttributeError", "error_message": "'RetrievalConfig' object has no attribute 'batch_size'", "stack_trace": "Traceback (most recent call last):\n  File \"/home/ubuntu/PycharmProjects/pythonRAG/services/retriever.py\", line 125, in _rerank_results\n    scores = self.reranker.predict(pairs, batch_size=self.config.batch_size)\nAttributeError: 'RetrievalConfig' object has no attribute 'batch_size'\n", "context": {"query": "\u5934\u90e8\u6c89\u91cd\u75db\u80c0\uff0c\u75db\u52bf\u7f13\u6162\uff0c\u9047\u9634\u96e8\u5929\u52a0\u91cd", "num_results": 60}}
{"asctime": "2025-09-08 22:03:17,516", "name": "enterprise_rag", "levelname": "INFO", "message": "retrieval_completed", "query": "\u5934\u90e8\u6c89\u91cd\u75db\u80c0\uff0c\u75db\u52bf\u7f13\u6162\uff0c\u9047\u9634\u96e8\u5929\u52a0\u91cd", "num_results": 8, "retrieval_time": 0.3878624439239502}
{"asctime": "2025-09-08 22:09:42,093", "name": "enterprise_rag", "levelname": "INFO", "message": "query_received", "query": "\uff0c\u60ca\u60d5\u4e0d\u5b89\uff0c\u591c\u5bd0\u4e0d\u5b89", "user_id": "user_console_001", "metadata": {}}
{"asctime": "2025-09-08 22:09:42,118", "name": "enterprise_rag", "levelname": "INFO", "message": "Embedded 1 sentences in 0.02s"}
{"asctime": "2025-09-08 22:09:42,122", "name": "enterprise_rag", "levelname": "INFO", "message": "Dense retrieval: 20 results"}
{"asctime": "2025-09-08 22:09:42,123", "name": "enterprise_rag", "levelname": "INFO", "message": "Sparse retrieval: 40 results"}
{"asctime": "2025-09-08 22:09:42,123", "name": "enterprise_rag", "levelname": "ERROR", "message": "Error occurred: AttributeError - 'RetrievalConfig' object has no attribute 'batch_size'\nTraceback (most recent call last):\n  File \"/home/ubuntu/PycharmProjects/pythonRAG/services/retriever.py\", line 125, in _rerank_results\n    scores = self.reranker.predict(pairs, batch_size=self.config.batch_size)\nAttributeError: 'RetrievalConfig' object has no attribute 'batch_size'\n", "error_type": "AttributeError", "error_message": "'RetrievalConfig' object has no attribute 'batch_size'", "stack_trace": "Traceback (most recent call last):\n  File \"/home/ubuntu/PycharmProjects/pythonRAG/services/retriever.py\", line 125, in _rerank_results\n    scores = self.reranker.predict(pairs, batch_size=self.config.batch_size)\nAttributeError: 'RetrievalConfig' object has no attribute 'batch_size'\n", "context": {"query": "\uff0c\u60ca\u60d5\u4e0d\u5b89\uff0c\u591c\u5bd0\u4e0d\u5b89", "num_results": 60}}
{"asctime": "2025-09-08 22:09:42,123", "name": "enterprise_rag", "levelname": "INFO", "message": "Initial rerank: top score = 0.7495, good results = 8"}
{"asctime": "2025-09-08 22:09:42,123", "name": "enterprise_rag", "levelname": "ERROR", "message": "Error occurred: AttributeError - 'RetrievalConfig' object has no attribute 'batch_size'\nTraceback (most recent call last):\n  File \"/home/ubuntu/PycharmProjects/pythonRAG/services/retriever.py\", line 125, in _rerank_results\n    scores = self.reranker.predict(pairs, batch_size=self.config.batch_size)\nAttributeError: 'RetrievalConfig' object has no attribute 'batch_size'\n", "error_type": "AttributeError", "error_message": "'RetrievalConfig' object has no attribute 'batch_size'", "stack_trace": "Traceback (most recent call last):\n  File \"/home/ubuntu/PycharmProjects/pythonRAG/services/retriever.py\", line 125, in _rerank_results\n    scores = self.reranker.predict(pairs, batch_size=self.config.batch_size)\nAttributeError: 'RetrievalConfig' object has no attribute 'batch_size'\n", "context": {"query": "\uff0c\u60ca\u60d5\u4e0d\u5b89\uff0c\u591c\u5bd0\u4e0d\u5b89", "num_results": 60}}
{"asctime": "2025-09-08 22:09:42,124", "name": "enterprise_rag", "levelname": "INFO", "message": "retrieval_completed", "query": "\uff0c\u60ca\u60d5\u4e0d\u5b89\uff0c\u591c\u5bd0\u4e0d\u5b89", "num_results": 8, "retrieval_time": 0.029751300811767578}
{"asctime": "2025-09-08 22:12:55,856", "name": "enterprise_rag", "levelname": "INFO", "message": "query_received", "query": "\u53e3\u81ed\uff0c\u6e34\u996e", "user_id": "user_console_001", "metadata": {}}
{"asctime": "2025-09-08 22:12:55,874", "name": "enterprise_rag", "levelname": "INFO", "message": "Embedded 1 sentences in 0.01s"}
{"asctime": "2025-09-08 22:12:55,879", "name": "enterprise_rag", "levelname": "INFO", "message": "Dense retrieval: 20 results"}
{"asctime": "2025-09-08 22:12:55,879", "name": "enterprise_rag", "levelname": "INFO", "message": "Sparse retrieval: 40 results"}
{"asctime": "2025-09-08 22:12:55,879", "name": "enterprise_rag", "levelname": "ERROR", "message": "Error occurred: AttributeError - 'RetrievalConfig' object has no attribute 'batch_size'\nTraceback (most recent call last):\n  File \"/home/ubuntu/PycharmProjects/pythonRAG/services/retriever.py\", line 125, in _rerank_results\n    scores = self.reranker.predict(pairs, batch_size=self.config.batch_size)\nAttributeError: 'RetrievalConfig' object has no attribute 'batch_size'\n", "error_type": "AttributeError", "error_message": "'RetrievalConfig' object has no attribute 'batch_size'", "stack_trace": "Traceback (most recent call last):\n  File \"/home/ubuntu/PycharmProjects/pythonRAG/services/retriever.py\", line 125, in _rerank_results\n    scores = self.reranker.predict(pairs, batch_size=self.config.batch_size)\nAttributeError: 'RetrievalConfig' object has no attribute 'batch_size'\n", "context": {"query": "\u53e3\u81ed\uff0c\u6e34\u996e", "num_results": 60}}
{"asctime": "2025-09-08 22:12:55,879", "name": "enterprise_rag", "levelname": "INFO", "message": "Initial rerank: top score = 0.7335, good results = 8"}
{"asctime": "2025-09-08 22:12:55,879", "name": "enterprise_rag", "levelname": "ERROR", "message": "Error occurred: AttributeError - 'RetrievalConfig' object has no attribute 'batch_size'\nTraceback (most recent call last):\n  File \"/home/ubuntu/PycharmProjects/pythonRAG/services/retriever.py\", line 125, in _rerank_results\n    scores = self.reranker.predict(pairs, batch_size=self.config.batch_size)\nAttributeError: 'RetrievalConfig' object has no attribute 'batch_size'\n", "error_type": "AttributeError", "error_message": "'RetrievalConfig' object has no attribute 'batch_size'", "stack_trace": "Traceback (most recent call last):\n  File \"/home/ubuntu/PycharmProjects/pythonRAG/services/retriever.py\", line 125, in _rerank_results\n    scores = self.reranker.predict(pairs, batch_size=self.config.batch_size)\nAttributeError: 'RetrievalConfig' object has no attribute 'batch_size'\n", "context": {"query": "\u53e3\u81ed\uff0c\u6e34\u996e", "num_results": 60}}
{"asctime": "2025-09-08 22:12:55,879", "name": "enterprise_rag", "levelname": "INFO", "message": "retrieval_completed", "query": "\u53e3\u81ed\uff0c\u6e34\u996e", "num_results": 8, "retrieval_time": 0.02206730842590332}
{"asctime": "2025-09-08 22:13:24,239", "name": "enterprise_rag", "levelname": "INFO", "message": "query_received", "query": "\u5934\u90e8\u6c89\u91cd\u75db\u80c0\uff0c\u75db\u52bf\u7f13\u6162\uff0c\u9047\u9634\u96e8\u5929\u52a0\u91cd", "user_id": "user_console_001", "metadata": {}}
{"asctime": "2025-09-08 22:13:24,241", "name": "enterprise_rag", "levelname": "INFO", "message": "retrieval_completed", "query": "\u5934\u90e8\u6c89\u91cd\u75db\u80c0\uff0c\u75db\u52bf\u7f13\u6162\uff0c\u9047\u9634\u96e8\u5929\u52a0\u91cd", "num_results": 8, "retrieval_time": 0.0013427734375}
{"asctime": "2025-09-08 22:13:28,919", "name": "enterprise_rag", "levelname": "INFO", "message": "query_received", "query": "\u5934\u90e8\u6c89\u91cd\u75db\u80c0\uff0c\u75db\u52bf\u7f13\u6162\uff0c\u9047\u9634\u96e8\u5929\u52a0\u91cd", "user_id": "user_console_001", "metadata": {}}
{"asctime": "2025-09-08 22:13:28,921", "name": "enterprise_rag", "levelname": "INFO", "message": "retrieval_completed", "query": "\u5934\u90e8\u6c89\u91cd\u75db\u80c0\uff0c\u75db\u52bf\u7f13\u6162\uff0c\u9047\u9634\u96e8\u5929\u52a0\u91cd", "num_results": 8, "retrieval_time": 0.0012810230255126953}
